2020-02-27 00:13:43,582 ERROR: Exception on /reset_password_request [POST] [in /home/artem/PycharmProjects/Flask/flask_project_1/microblog/venv/lib/python3.6/site-packages/flask/app.py:1891]
Traceback (most recent call last):
  File "/home/artem/PycharmProjects/Flask/flask_project_1/microblog/venv/lib/python3.6/site-packages/flask/app.py", line 2446, in wsgi_app
    response = self.full_dispatch_request()
  File "/home/artem/PycharmProjects/Flask/flask_project_1/microblog/venv/lib/python3.6/site-packages/flask/app.py", line 1951, in full_dispatch_request
    rv = self.handle_user_exception(e)
  File "/home/artem/PycharmProjects/Flask/flask_project_1/microblog/venv/lib/python3.6/site-packages/flask/app.py", line 1820, in handle_user_exception
    reraise(exc_type, exc_value, tb)
  File "/home/artem/PycharmProjects/Flask/flask_project_1/microblog/venv/lib/python3.6/site-packages/flask/_compat.py", line 39, in reraise
    raise value
  File "/home/artem/PycharmProjects/Flask/flask_project_1/microblog/venv/lib/python3.6/site-packages/flask/app.py", line 1949, in full_dispatch_request
    rv = self.dispatch_request()
  File "/home/artem/PycharmProjects/Flask/flask_project_1/microblog/venv/lib/python3.6/site-packages/flask/app.py", line 1935, in dispatch_request
    return self.view_functions[rule.endpoint](**req.view_args)
  File "/home/artem/PycharmProjects/Flask/flask_project_1/microblog/app/routes.py", line 200, in reset_password_request
    send_password_reset_email(user)
  File "/home/artem/PycharmProjects/Flask/flask_project_1/microblog/app/email.py", line 21, in send_password_reset_email
    user=user, token=token))
  File "/home/artem/PycharmProjects/Flask/flask_project_1/microblog/app/email.py", line 10, in send_email
    mail.send(msg)
  File "/home/artem/PycharmProjects/Flask/flask_project_1/microblog/venv/lib/python3.6/site-packages/flask_mail.py", line 491, in send
    with self.connect() as connection:
  File "/home/artem/PycharmProjects/Flask/flask_project_1/microblog/venv/lib/python3.6/site-packages/flask_mail.py", line 144, in __enter__
    self.host = self.configure_host()
  File "/home/artem/PycharmProjects/Flask/flask_project_1/microblog/venv/lib/python3.6/site-packages/flask_mail.py", line 165, in configure_host
    host.login(self.mail.username, self.mail.password)
  File "/usr/lib/python3.6/smtplib.py", line 730, in login
    raise last_exception
  File "/usr/lib/python3.6/smtplib.py", line 721, in login
    initial_response_ok=initial_response_ok)
  File "/usr/lib/python3.6/smtplib.py", line 642, in auth
    raise SMTPAuthenticationError(code, resp)
smtplib.SMTPAuthenticationError: (535, b'5.7.8 Username and Password not accepted. Learn more at\n5.7.8  https://support.google.com/mail/?p=BadCredentials r12sm1884040ljh.105 - gsmtp')
2020-02-27 00:16:09,290 INFO: Microblog startup [in /home/artem/PycharmProjects/Flask/flask_project_1/microblog/app/routes.py:157]
2020-02-27 00:29:47,747 INFO: Microblog startup [in /home/artem/PycharmProjects/Flask/flask_project_1/microblog/app/routes.py:157]
